Workbook

Sheet Cómo se usa
A1: Plataforma IWL · pruebas
C2: Recorrido de todos los módulos. Una fila por cosa que probar.
A4: Cómo se rellena
A5: Resultado | B5: OK / Falla / A medias / Bloqueado / No aplica | C5: Es un desplegable: se pinta solo del color que toca.
A6: Gravedad | B6: Bloqueante / Importante / Menor / Cosmético | C6: Solo si falla. Bloqueante es lo que impide seguir probando o no se puede enseñar a nadie.
A7: Comentarios | B7: Texto libre | C7: Qué viste exactamente. Si puedes, con qué datos y en qué pantalla. Una captura vale por tres frases.
A9: Para moverse
A10: Filtros | B10: Fila 1 | C10: Cada columna filtra. Para hacer un módulo entero, filtra por Módulo.
A11: Columnas congeladas | B11: Nº a Entra como | C11: Se quedan fijas al desplazar a la derecha.
A12: Resumen | B12: Pestaña «Resumen» | C12: Cuenta sola según vas rellenando. No hay que tocar nada.
A14: Dónde probar
A15: En la nube | B15: https://iwl-platform.vercel.app | C15: Lo que de verdad va a usar la gente. Ojo: lo que escribas aquí queda.
A16: En local | B16: npm run db:reset && npm run dev | C16: Para romper cosas sin miedo. Se reinicia entero en un minuto.
A17: Correos en local | B17: http://127.0.0.1:54324 | C17: Los enlaces de entrada no salen a internet: caen en esa bandeja.
A19: Con qué cuenta entrar (en local)
A20: Contraseña común | B20: iwl-local-2026 | C20: Solo en local. En la nube cada cuenta tiene la suya, en .accesos-nube.md
A21: admin@iwl.test | B21: admin_iwl | C21: Todo, incluida la configuración del programa
A22: programa@iwl.test | B22: equipo_iwl | C22: Toda la cartera, pero no la configuración
A23: revisor@niage.test | B23: revisor_niage | C23: Marea Clínica y Raíz Sensórica
A24: revisor2@niage.test | B24: revisor_niage | C24: Vega Predictiva
A25: mentor@iwl.test | B25: mentor | C25: Coordina Marea Clínica, apoya en Raíz Sensórica
A26: mentor2@iwl.test | B26: mentor | C26: Coordina Raíz Sensórica, apoya en Marea Clínica
A27: fundadora@marea.test | B27: fundadora | C27: Marea Clínica
A28: fundadora@vega.test | B28: fundadora | C28: Vega Predictiva
A29: fundadora@raiz.test | B29: fundadora | C29: Raíz Sensórica
A30: cto@marea.test | B30: fundadora | C30: Marea Clínica, como segunda del equipo
A32: Por dónde empezar
A33: 1 | B33: Módulos 2 a 7 | C33: El embudo de punta a punta: convocatoria, candidatura, NDA, acuerdo y firma. Es lo más nuevo y lo menos rodado.
A34: 2 | B34: Módulo 21 | C34: Permisos. Entrando como quien MENOS puede: ahí es donde se ven los agujeros.
A35: 3 | B35: El resto | C35: Por orden, o por lo que más te interese enseñar.
A37: Dos cosas que conviene saber
A38: Lo sin medir no es un cero | C38: Un proyecto sin evaluar tiene que parecer sin evaluar («—»), no malo. Si ves un 0, es un fallo.
A39: Nadie valida su propio trabajo | C39: Una fundadora no puntúa ni valida sus puntos. Si en algún sitio puede, es un fallo grave.

Sheet Pruebas
A1: Nº | B1: Módulo | C1: Pantalla | D1: Entra como | E1: Qué se prueba | F1: Pasos | G1: Qué debería pasar | H1: Resultado | I1: Gravedad | J1: Comentarios
A2: 1.01 | B2: 1. Acceso y cuentas | C2: /entrar | D2: admin@iwl.test | E2: Entrar con correo y contraseña | F2: Escribir correo y contraseña y pulsar Entrar. | G2: Entra y aterriza en la cartera. | H2: OK | J2: RONDA 1 · Carlos y Cecilia salen sin compañía asignada, no se puede ver nada. Juan tiene otra interfaz, diferente al resto
A3: 1.02 | B3: 1. Acceso y cuentas | C3: /entrar | D3: cualquiera | E3: Contraseña equivocada | F3: Escribir una contraseña que no es y pulsar Entrar. | G3: Dice qué ha pasado y qué hacer, sin signos de exclamación. No se queda colgado.
A4: 1.03 | B4: 1. Acceso y cuentas | C4: /entrar | D4: — | E4: No hay autoservicio | F4: Buscar en la pantalla de entrada alguna forma de crear una cuenta. | G4: No la hay. Las cuentas las crea la dirección de IWL.
A5: 1.04 | B5: 1. Acceso y cuentas | C5: / | D5: fundadora@marea.test | E5: La raíz lleva a donde toca según quién eres | F5: Entrar y abrir la dirección raíz. | G5: Una fundadora cae en su proyecto; IWL, en la cartera.
A6: 1.05 | B6: 1. Acceso y cuentas | C6: /cartera | D6: fundadora@marea.test | E6: Una fundadora no entra en la cartera | F6: Estando dentro como fundadora, escribir /cartera en la barra de direcciones. | G6: La devuelve a su proyecto. No ve la cartera ni de refilón.
A7: 1.06 | B7: 1. Acceso y cuentas | C7: /admin | D7: programa@iwl.test | E7: El equipo de IWL no configura el programa | F7: Entrar como equipo_iwl y escribir /admin en la barra. | G7: No entra. La configuración es solo de la dirección.
A8: 1.07 | B8: 1. Acceso y cuentas | C8: /perfil | D8: fundadora@marea.test | E8: Cambiar mi propia contraseña | F8: Abrir Mi cuenta, poner contraseña nueva y guardar. Salir y volver a entrar con ella. | G8: Se guarda y la nueva funciona.
A9: 1.08 | B9: 1. Acceso y cuentas | C9: /sin-compania | D9: una cuenta recién creada | E9: Quien no tiene compañía lo entiende | F9: Entrar con una cuenta recién creada y sin asignar. | G9: Dice qué pasa y a quién pedírselo, no una pantalla en blanco.
A10: 1.09 | B10: 1. Acceso y cuentas | C10: Cualquiera | D10: — | E10: Salir | F10: Pulsar Salir desde cualquier pantalla. | G10: Vuelve a /entrar y la sesión queda cerrada de verdad (atrás no reabre nada).
A11: 2.01 | B11: 2. Convocatoria | C11: /embudo | D11: admin@iwl.test | E11: Abrir la convocatoria de una cohorte | F11: Embudo → Convocatoria → elegir cohorte, marcar abierta, guardar. | G11: Confirma. Arriba aparece el aviso de que esa convocatoria está abierta. | H11: OK | J11: RONDA 1 · Me parece un poco raro como está explicado o como marcar abierta o cerrada
A12: 2.02 | B12: 2. Convocatoria | C12: /embudo | D12: admin@iwl.test | E12: La dirección que se reparte está a la vista | F12: Con la convocatoria abierta, mirar el bloque «Reparte esta dirección» y pulsar Copiar. | G12: Se ve la dirección entera y se copia al portapapeles.
A13: 2.03 | B13: 2. Convocatoria | C13: /presentarse | D13: sin cuenta | E13: Con la convocatoria abierta, el formulario sale | F13: Abrir la dirección copiada en una ventana privada. | G13: Sale el formulario de candidatura, sin pedir cuenta.
A14: 2.04 | B14: 2. Convocatoria | C14: /embudo | D14: admin@iwl.test | E14: Cerrar la convocatoria | F14: Desmarcar abierta y guardar. Volver a abrir /presentarse en ventana privada. | G14: Dice que no hay convocatoria en curso Y da una dirección de correo para avisar. Antes decía «escríbenos» sin decir dónde. | H14: OK | J14: RONDA 1 · Hay un mensaje que dice: "si quieres que te avísemos, escríbenos" Ahí quizás se debería de dar el tipo de contacto que se requiera para que nos escriban, un correo, el instagram, etc
A15: 2.05 | B15: 2. Convocatoria | C15: /embudo | D15: admin@iwl.test | E15: Fecha de cierre | F15: Abrir la convocatoria con una fecha de cierre y mirar el texto de arriba. | G15: Dice hasta cuándo está abierta.
A16: 3.01 | B16: 3. Presentar candidatura | C16: /presentarse | D16: sin cuenta | E16: Presentarse con todo relleno | F16: Rellenar los campos, dejar dos enlaces de Drive y enviar. | G16: «Recibida. Gracias.» y debajo el enlace privado con botón de copiar. | H16: OK | J16: RONDA 1 · Igual que antes, mensaje de "escríbenos" pero no dice donde
A17: 3.02 | B17: 3. Presentar candidatura | C17: /presentarse | D17: sin cuenta | E17: Solo lo obligatorio | F17: Rellenar lo que lleva asterisco: startup, en qué punto estáis, tu nombre y tu correo. Enviar. | G17: Se acepta. El resto es opcional de verdad. | H17: OK | J17: RONDA 1 · Añadir el típico asterisco luego de el espacio a rellenar para que se identifique como obligatorio
A18: 3.03 | B18: 3. Presentar candidatura | C18: /presentarse | D18: sin cuenta | E18: La etapa no se puede esquivar | F18: Mirar el desplegable «¿En qué punto estáis?» e intentar enviar sin tocarlo. | G18: Ya no existe «Prefiero no decirlo». Pone «Elige una» y no deja enviar sin elegir.
A19: 3.04 | B19: 3. Presentar candidatura | C19: /presentarse | D19: sin cuenta | E19: Un porcentaje escrito a mano (el caso dronesec) | F19: En «Liderazgo femenino (%)» escribir «50 %». También probar «33,3». | G19: Se acepta. Llega como número, no se rechaza por el signo ni por la coma. | H19: Falla | I19: Menor | J19: RONDA 1 · Si que rechaza el signo y la coma, no lo dice pero es por eso
A20: 3.05 | B20: 3. Presentar candidatura | C20: /presentarse | D20: sin cuenta | E20: Cuando algo falla, se dice cuál y no se borra nada | F20: Rellenarlo entero y poner «la mitad» en el porcentaje. Enviar. | G20: Dice «Revisa este campo: liderazgo femenino», lo marca en rojo, y TODO lo demás sigue escrito.
A21: 3.06 | B21: 3. Presentar candidatura | C21: /presentarse | D21: sin cuenta | E21: Correo mal escrito | F21: Poner un correo sin arroba y enviar. | G21: Lo señala sin perder el resto de lo escrito.
A22: 3.07 | B22: 3. Presentar candidatura | C22: /candidatura/<testigo> | D22: sin cuenta | E22: El enlace privado abre su candidatura | F22: Pegar el enlace que dio el formulario en otra ventana. | G22: Ve su nombre, el estado «Recibida» y lo que mandó.
A23: 3.08 | B23: 3. Presentar candidatura | C23: /candidatura/<testigo> | D23: sin cuenta | E23: Añadir material que se olvidó | F23: En su enlace, Añadir un documento: título y URL. Añadir. | G23: «Añadido. Gracias.» y el documento aparece en la lista.
A24: 3.09 | B24: 3. Presentar candidatura | C24: /candidatura/xxxx | D24: sin cuenta | E24: Un enlace inventado no dice si existe | F24: Escribir un testigo cualquiera inventado. | G24: 404 a secas. No distingue entre «no existe» y «no es tuyo». | J24: RONDA 1 · No entiendo este punto
A25: 4.01 | B25: 4. Alta a mano | C25: /embudo | D25: admin@iwl.test | E25: Dar de alta una candidatura conocida en un evento | F25: Embudo → Dar de alta una candidatura a mano: cohorte, nombre, contacto, correo. | G25: Confirma que entra en el embudo y aparece en la lista de abiertas.
A26: 4.02 | B26: 4. Alta a mano | C26: /embudo/<id> | D26: admin@iwl.test | E26: El enlace de la invitada se ve para mandarlo | F26: Abrir su ficha en el embudo y buscar el enlace privado. | G26: Está a la vista, se puede copiar y mandar a mano.
A27: 4.03 | B27: 4. Alta a mano | C27: /candidatura/<testigo> | D27: sin cuenta | E27: A la invitada se le pide que se presente | F27: Abrir el enlace de una candidatura dada de alta por IWL. | G27: Dice «Cuéntanos quiénes sois», NO «Recibida, gracias». Y tiene formulario para contarlo.
A28: 4.04 | B28: 4. Alta a mano | C28: /candidatura/<testigo> | D28: sin cuenta | E28: La invitada completa su propia ficha | F28: Rellenar descripción, punto en que están, web, equipo. Guardar. | G28: «Guardado. Gracias.» y lo escrito queda visible.
A29: 4.05 | B29: 4. Alta a mano | C29: /candidatura/<testigo> | D29: sin cuenta | E29: Un formulario a medias no borra lo que ya había | F29: IWL apunta el sector al dar de alta; ella deja ese campo vacío y guarda. | G29: El sector se queda como estaba. No se vacía.
A30: 5.01 | B30: 5. Recorrido del embudo | C30: /embudo | D30: admin@iwl.test | E30: La foto del embudo cuadra | F30: Mirar las cuatro cifras de arriba y el recorrido paso a paso. | G30: En proceso, firmadas, descartadas y conversión cuadran con las listas de abajo.
A31: 5.02 | B31: 5. Recorrido del embudo | C31: /embudo | D31: admin@iwl.test | E31: La conversión no miente con pocos datos | F31: Mirar la conversión con menos de cinco candidaturas cerradas. | G31: Pone «—» y explica que hacen falta cinco. No inventa un porcentaje.
A32: 5.03 | B32: 5. Recorrido del embudo | C32: /embudo/<id> | D32: admin@iwl.test | E32: Mover de paso | F32: Pasar una candidatura de presentada a en revisión, y luego a reunión. | G32: Cambia el paso y queda anotado en el historial con fecha.
A33: 5.04 | B33: 5. Recorrido del embudo | C33: /embudo/<id> | D33: admin@iwl.test | E33: Anotar lo que pasó en la reunión | F33: Anotar un evento con lo hablado en la reunión y en el comité. | G33: Queda en el historial, lo más reciente arriba.
A34: 5.05 | B34: 5. Recorrido del embudo | C34: /embudo/<id> | D34: admin@iwl.test | E34: Preseleccionar | F34: Mover a preseleccionada después del comité. | G34: Cambia de paso y la cuenta del recorrido se mueve con ella. | H34: OK | J34: RONDA 1 · Hay 2 maneras de moverlo, con el botón o el desplegable, si la muevo con el boton, y luego la vuelvo a mover con el desplegable, se queda pegado los dos iconos de "movido" a cada lado
A35: 5.06 | B35: 5. Recorrido del embudo | C35: /embudo/<id> | D35: admin@iwl.test | E35: Descartar con su motivo | F35: Descartar una candidatura escribiendo el motivo. | G35: Sale de las abiertas, entra en descartadas, y queda apuntado EN QUÉ PASO se cayó.
A36: 5.07 | B36: 5. Recorrido del embudo | C36: /embudo | D36: admin@iwl.test | E36: Dónde se cae la gente | F36: Mirar el bloque de descartadas y las pastillas por paso. | G36: Dice cuántas se cayeron en cada paso. Es la pregunta por la que se cambia un proceso.
A37: 5.08 | B37: 5. Recorrido del embudo | C37: /embudo/<id> | D37: admin@iwl.test | E37: Reabrir una descartada | F37: Reabrir una que se descartó por error. | G37: Vuelve a las abiertas, al paso donde estaba. | H37: OK | J37: RONDA 1 · Al tener enlaces añadidos, la interfaz se desfasa
A38: 5.09 | B38: 5. Recorrido del embudo | C38: /candidatura/<testigo> | D38: sin cuenta | E38: La descartada NO lee el motivo | F38: Abrir el enlace de una candidatura descartada. | G38: Dice «Proceso cerrado» y que se lo contarán. El motivo NO aparece, y tampoco la caja de documentos vacía reprochándole lo que no mandó. | H38: OK | J38: RONDA 1 · Lo único, aparece también el recuadro de "Lo que nos has mandado. Todavía no nos has mandado ningún documento"
A39: 5.10 | B39: 5. Recorrido del embudo | C39: /candidatura/<testigo> | D39: sin cuenta | E39: La candidata ve momentos, no jerga | F39: Mirar el enlace de una que está en comité. | G39: Dice «En estudio». No dice «comité» ni el paso exacto, y NO le pide que se presente: ya hemos hablado con ella. | H39: Falla | I39: Importante | J39: RONDA 1 · Aparece todo el formulario de "cuentanos quienes sois"
A40: 5.11 | B40: 5. Recorrido del embudo | C40: /candidatura/<testigo> | D40: sin cuenta | E40: Corregir un dato estando ya avanzada | F40: En una candidatura en comité, buscar cómo cambiar la web o el teléfono. | G40: Está plegado bajo «Corregir nuestros datos». Existe, pero no es lo primero que ve.
...

Sheet Resumen
A1: Cómo va
A3: Módulo | B3: Pruebas | C3: OK | D3: Falla | E3: A medias | F3: Bloqueado | G3: Sin probar
A4: 1. Acceso y cuentas | B4: =COUNTIF(Pruebas!$B$2:$B$175,"1. Acceso y cuentas") | C4: =COUNTIFS(Pruebas!$B$2:$B$175,"1. Acceso y cuentas",Pruebas!$H$2:$H$175,"OK") | D4: =COUNTIFS(Pruebas!$B$2:$B$175,"1. Acceso y cuentas",Pruebas!$H$2:$H$175,"Falla") | E4: =COUNTIFS(Pruebas!$B$2:$B$175,"1. Acceso y cuentas",Pruebas!$H$2:$H$175,"A medias") | F4: =COUNTIFS(Pruebas!$B$2:$B$175,"1. Acceso y cuentas",Pruebas!$H$2:$H$175,"Bloqueado") | G4: =COUNTIFS(Pruebas!$B$2:$B$175,"1. Acceso y cuentas",Pruebas!$H$2:$H$175,"")
A5: 2. Convocatoria | B5: =COUNTIF(Pruebas!$B$2:$B$175,"2. Convocatoria") | C5: =COUNTIFS(Pruebas!$B$2:$B$175,"2. Convocatoria",Pruebas!$H$2:$H$175,"OK") | D5: =COUNTIFS(Pruebas!$B$2:$B$175,"2. Convocatoria",Pruebas!$H$2:$H$175,"Falla") | E5: =COUNTIFS(Pruebas!$B$2:$B$175,"2. Convocatoria",Pruebas!$H$2:$H$175,"A medias") | F5: =COUNTIFS(Pruebas!$B$2:$B$175,"2. Convocatoria",Pruebas!$H$2:$H$175,"Bloqueado") | G5: =COUNTIFS(Pruebas!$B$2:$B$175,"2. Convocatoria",Pruebas!$H$2:$H$175,"")
A6: 3. Presentar candidatura | B6: =COUNTIF(Pruebas!$B$2:$B$175,"3. Presentar candidatura") | C6: =COUNTIFS(Pruebas!$B$2:$B$175,"3. Presentar candidatura",Pruebas!$H$2:$H$175,"OK") | D6: =COUNTIFS(Pruebas!$B$2:$B$175,"3. Presentar candidatura",Pruebas!$H$2:$H$175,"Falla") | E6: =COUNTIFS(Pruebas!$B$2:$B$175,"3. Presentar candidatura",Pruebas!$H$2:$H$175,"A medias") | F6: =COUNTIFS(Pruebas!$B$2:$B$175,"3. Presentar candidatura",Pruebas!$H$2:$H$175,"Bloqueado") | G6: =COUNTIFS(Pruebas!$B$2:$B$175,"3. Presentar candidatura",Pruebas!$H$2:$H$175,"")
A7: 4. Alta a mano | B7: =COUNTIF(Pruebas!$B$2:$B$175,"4. Alta a mano") | C7: =COUNTIFS(Pruebas!$B$2:$B$175,"4. Alta a mano",Pruebas!$H$2:$H$175,"OK") | D7: =COUNTIFS(Pruebas!$B$2:$B$175,"4. Alta a mano",Pruebas!$H$2:$H$175,"Falla") | E7: =COUNTIFS(Pruebas!$B$2:$B$175,"4. Alta a mano",Pruebas!$H$2:$H$175,"A medias") | F7: =COUNTIFS(Pruebas!$B$2:$B$175,"4. Alta a mano",Pruebas!$H$2:$H$175,"Bloqueado") | G7: =COUNTIFS(Pruebas!$B$2:$B$175,"4. Alta a mano",Pruebas!$H$2:$H$175,"")
A8: 5. Recorrido del embudo | B8: =COUNTIF(Pruebas!$B$2:$B$175,"5. Recorrido del embudo") | C8: =COUNTIFS(Pruebas!$B$2:$B$175,"5. Recorrido del embudo",Pruebas!$H$2:$H$175,"OK") | D8: =COUNTIFS(Pruebas!$B$2:$B$175,"5. Recorrido del embudo",Pruebas!$H$2:$H$175,"Falla") | E8: =COUNTIFS(Pruebas!$B$2:$B$175,"5. Recorrido del embudo",Pruebas!$H$2:$H$175,"A medias") | F8: =COUNTIFS(Pruebas!$B$2:$B$175,"5. Recorrido del embudo",Pruebas!$H$2:$H$175,"Bloqueado") | G8: =COUNTIFS(Pruebas!$B$2:$B$175,"5. Recorrido del embudo",Pruebas!$H$2:$H$175,"")
A9: 6. NDA y DD de candidata | B9: =COUNTIF(Pruebas!$B$2:$B$175,"6. NDA y DD de candidata") | C9: =COUNTIFS(Pruebas!$B$2:$B$175,"6. NDA y DD de candidata",Pruebas!$H$2:$H$175,"OK") | D9: =COUNTIFS(Pruebas!$B$2:$B$175,"6. NDA y DD de candidata",Pruebas!$H$2:$H$175,"Falla") | E9: =COUNTIFS(Pruebas!$B$2:$B$175,"6. NDA y DD de candidata",Pruebas!$H$2:$H$175,"A medias") | F9: =COUNTIFS(Pruebas!$B$2:$B$175,"6. NDA y DD de candidata",Pruebas!$H$2:$H$175,"Bloqueado") | G9: =COUNTIFS(Pruebas!$B$2:$B$175,"6. NDA y DD de candidata",Pruebas!$H$2:$H$175,"")
A10: 7. Acuerdo y firma | B10: =COUNTIF(Pruebas!$B$2:$B$175,"7. Acuerdo y firma") | C10: =COUNTIFS(Pruebas!$B$2:$B$175,"7. Acuerdo y firma",Pruebas!$H$2:$H$175,"OK") | D10: =COUNTIFS(Pruebas!$B$2:$B$175,"7. Acuerdo y firma",Pruebas!$H$2:$H$175,"Falla") | E10: =COUNTIFS(Pruebas!$B$2:$B$175,"7. Acuerdo y firma",Pruebas!$H$2:$H$175,"A medias") | F10: =COUNTIFS(Pruebas!$B$2:$B$175,"7. Acuerdo y firma",Pruebas!$H$2:$H$175,"Bloqueado") | G10: =COUNTIFS(Pruebas!$B$2:$B$175,"7. Acuerdo y firma",Pruebas!$H$2:$H$175,"")
A11: 8. Cartera y cohorte | B11: =COUNTIF(Pruebas!$B$2:$B$175,"8. Cartera y cohorte") | C11: =COUNTIFS(Pruebas!$B$2:$B$175,"8. Cartera y cohorte",Pruebas!$H$2:$H$175,"OK") | D11: =COUNTIFS(Pruebas!$B$2:$B$175,"8. Cartera y cohorte",Pruebas!$H$2:$H$175,"Falla") | E11: =COUNTIFS(Pruebas!$B$2:$B$175,"8. Cartera y cohorte",Pruebas!$H$2:$H$175,"A medias") | F11: =COUNTIFS(Pruebas!$B$2:$B$175,"8. Cartera y cohorte",Pruebas!$H$2:$H$175,"Bloqueado") | G11: =COUNTIFS(Pruebas!$B$2:$B$175,"8. Cartera y cohorte",Pruebas!$H$2:$H$175,"")
A12: 9. Comparativa | B12: =COUNTIF(Pruebas!$B$2:$B$175,"9. Comparativa") | C12: =COUNTIFS(Pruebas!$B$2:$B$175,"9. Comparativa",Pruebas!$H$2:$H$175,"OK") | D12: =COUNTIFS(Pruebas!$B$2:$B$175,"9. Comparativa",Pruebas!$H$2:$H$175,"Falla") | E12: =COUNTIFS(Pruebas!$B$2:$B$175,"9. Comparativa",Pruebas!$H$2:$H$175,"A medias") | F12: =COUNTIFS(Pruebas!$B$2:$B$175,"9. Comparativa",Pruebas!$H$2:$H$175,"Bloqueado") | G12: =COUNTIFS(Pruebas!$B$2:$B$175,"9. Comparativa",Pruebas!$H$2:$H$175,"")
A13: 10. Resumen de compañía | B13: =COUNTIF(Pruebas!$B$2:$B$175,"10. Resumen de compañía") | C13: =COUNTIFS(Pruebas!$B$2:$B$175,"10. Resumen de compañía",Pruebas!$H$2:$H$175,"OK") | D13: =COUNTIFS(Pruebas!$B$2:$B$175,"10. Resumen de compañía",Pruebas!$H$2:$H$175,"Falla") | E13: =COUNTIFS(Pruebas!$B$2:$B$175,"10. Resumen de compañía",Pruebas!$H$2:$H$175,"A medias") | F13: =COUNTIFS(Pruebas!$B$2:$B$175,"10. Resumen de compañía",Pruebas!$H$2:$H$175,"Bloqueado") | G13: =COUNTIFS(Pruebas!$B$2:$B$175,"10. Resumen de compañía",Pruebas!$H$2:$H$175,"")
A14: 11. Hoja de ruta | B14: =COUNTIF(Pruebas!$B$2:$B$175,"11. Hoja de ruta") | C14: =COUNTIFS(Pruebas!$B$2:$B$175,"11. Hoja de ruta",Pruebas!$H$2:$H$175,"OK") | D14: =COUNTIFS(Pruebas!$B$2:$B$175,"11. Hoja de ruta",Pruebas!$H$2:$H$175,"Falla") | E14: =COUNTIFS(Pruebas!$B$2:$B$175,"11. Hoja de ruta",Pruebas!$H$2:$H$175,"A medias") | F14: =COUNTIFS(Pruebas!$B$2:$B$175,"11. Hoja de ruta",Pruebas!$H$2:$H$175,"Bloqueado") | G14: =COUNTIFS(Pruebas!$B$2:$B$175,"11. Hoja de ruta",Pruebas!$H$2:$H$175,"")
A15: 12. Programa y Anexo | B15: =COUNTIF(Pruebas!$B$2:$B$175,"12. Programa y Anexo") | C15: =COUNTIFS(Pruebas!$B$2:$B$175,"12. Programa y Anexo",Pruebas!$H$2:$H$175,"OK") | D15: =COUNTIFS(Pruebas!$B$2:$B$175,"12. Programa y Anexo",Pruebas!$H$2:$H$175,"Falla") | E15: =COUNTIFS(Pruebas!$B$2:$B$175,"12. Programa y Anexo",Pruebas!$H$2:$H$175,"A medias") | F15: =COUNTIFS(Pruebas!$B$2:$B$175,"12. Programa y Anexo",Pruebas!$H$2:$H$175,"Bloqueado") | G15: =COUNTIFS(Pruebas!$B$2:$B$175,"12. Programa y Anexo",Pruebas!$H$2:$H$175,"")
A16: 13. Aportación de IWL | B16: =COUNTIF(Pruebas!$B$2:$B$175,"13. Aportación de IWL") | C16: =COUNTIFS(Pruebas!$B$2:$B$175,"13. Aportación de IWL",Pruebas!$H$2:$H$175,"OK") | D16: =COUNTIFS(Pruebas!$B$2:$B$175,"13. Aportación de IWL",Pruebas!$H$2:$H$175,"Falla") | E16: =COUNTIFS(Pruebas!$B$2:$B$175,"13. Aportación de IWL",Pruebas!$H$2:$H$175,"A medias") | F16: =COUNTIFS(Pruebas!$B$2:$B$175,"13. Aportación de IWL",Pruebas!$H$2:$H$175,"Bloqueado") | G16: =COUNTIFS(Pruebas!$B$2:$B$175,"13. Aportación de IWL",Pruebas!$H$2:$H$175,"")
A17: 14. Due diligence técnico | B17: =COUNTIF(Pruebas!$B$2:$B$175,"14. Due diligence técnico") | C17: =COUNTIFS(Pruebas!$B$2:$B$175,"14. Due diligence técnico",Pruebas!$H$2:$H$175,"OK") | D17: =COUNTIFS(Pruebas!$B$2:$B$175,"14. Due diligence técnico",Pruebas!$H$2:$H$175,"Falla") | E17: =COUNTIFS(Pruebas!$B$2:$B$175,"14. Due diligence técnico",Pruebas!$H$2:$H$175,"A medias") | F17: =COUNTIFS(Pruebas!$B$2:$B$175,"14. Due diligence técnico",Pruebas!$H$2:$H$175,"Bloqueado") | G17: =COUNTIFS(Pruebas!$B$2:$B$175,"14. Due diligence técnico",Pruebas!$H$2:$H$175,"")
A18: 15. Due diligence general | B18: =COUNTIF(Pruebas!$B$2:$B$175,"15. Due diligence general") | C18: =COUNTIFS(Pruebas!$B$2:$B$175,"15. Due diligence general",Pruebas!$H$2:$H$175,"OK") | D18: =COUNTIFS(Pruebas!$B$2:$B$175,"15. Due diligence general",Pruebas!$H$2:$H$175,"Falla") | E18: =COUNTIFS(Pruebas!$B$2:$B$175,"15. Due diligence general",Pruebas!$H$2:$H$175,"A medias") | F18: =COUNTIFS(Pruebas!$B$2:$B$175,"15. Due diligence general",Pruebas!$H$2:$H$175,"Bloqueado") | G18: =COUNTIFS(Pruebas!$B$2:$B$175,"15. Due diligence general",Pruebas!$H$2:$H$175,"")
A19: 16. Business plan | B19: =COUNTIF(Pruebas!$B$2:$B$175,"16. Business plan") | C19: =COUNTIFS(Pruebas!$B$2:$B$175,"16. Business plan",Pruebas!$H$2:$H$175,"OK") | D19: =COUNTIFS(Pruebas!$B$2:$B$175,"16. Business plan",Pruebas!$H$2:$H$175,"Falla") | E19: =COUNTIFS(Pruebas!$B$2:$B$175,"16. Business plan",Pruebas!$H$2:$H$175,"A medias") | F19: =COUNTIFS(Pruebas!$B$2:$B$175,"16. Business plan",Pruebas!$H$2:$H$175,"Bloqueado") | G19: =COUNTIFS(Pruebas!$B$2:$B$175,"16. Business plan",Pruebas!$H$2:$H$175,"")
A20: 17. KPI y updates | B20: =COUNTIF(Pruebas!$B$2:$B$175,"17. KPI y updates") | C20: =COUNTIFS(Pruebas!$B$2:$B$175,"17. KPI y updates",Pruebas!$H$2:$H$175,"OK") | D20: =COUNTIFS(Pruebas!$B$2:$B$175,"17. KPI y updates",Pruebas!$H$2:$H$175,"Falla") | E20: =COUNTIFS(Pruebas!$B$2:$B$175,"17. KPI y updates",Pruebas!$H$2:$H$175,"A medias") | F20: =COUNTIFS(Pruebas!$B$2:$B$175,"17. KPI y updates",Pruebas!$H$2:$H$175,"Bloqueado") | G20: =COUNTIFS(Pruebas!$B$2:$B$175,"17. KPI y updates",Pruebas!$H$2:$H$175,"")
A21: 18. Línea base | B21: =COUNTIF(Pruebas!$B$2:$B$175,"18. Línea base") | C21: =COUNTIFS(Pruebas!$B$2:$B$175,"18. Línea base",Pruebas!$H$2:$H$175,"OK") | D21: =COUNTIFS(Pruebas!$B$2:$B$175,"18. Línea base",Pruebas!$H$2:$H$175,"Falla") | E21: =COUNTIFS(Pruebas!$B$2:$B$175,"18. Línea base",Pruebas!$H$2:$H$175,"A medias") | F21: =COUNTIFS(Pruebas!$B$2:$B$175,"18. Línea base",Pruebas!$H$2:$H$175,"Bloqueado") | G21: =COUNTIFS(Pruebas!$B$2:$B$175,"18. Línea base",Pruebas!$H$2:$H$175,"")
A22: 19. Administración | B22: =COUNTIF(Pruebas!$B$2:$B$175,"19. Administración") | C22: =COUNTIFS(Pruebas!$B$2:$B$175,"19. Administración",Pruebas!$H$2:$H$175,"OK") | D22: =COUNTIFS(Pruebas!$B$2:$B$175,"19. Administración",Pruebas!$H$2:$H$175,"Falla") | E22: =COUNTIFS(Pruebas!$B$2:$B$175,"19. Administración",Pruebas!$H$2:$H$175,"A medias") | F22: =COUNTIFS(Pruebas!$B$2:$B$175,"19. Administración",Pruebas!$H$2:$H$175,"Bloqueado") | G22: =COUNTIFS(Pruebas!$B$2:$B$175,"19. Administración",Pruebas!$H$2:$H$175,"")
A23: 20. Informes | B23: =COUNTIF(Pruebas!$B$2:$B$175,"20. Informes") | C23: =COUNTIFS(Pruebas!$B$2:$B$175,"20. Informes",Pruebas!$H$2:$H$175,"OK") | D23: =COUNTIFS(Pruebas!$B$2:$B$175,"20. Informes",Pruebas!$H$2:$H$175,"Falla") | E23: =COUNTIFS(Pruebas!$B$2:$B$175,"20. Informes",Pruebas!$H$2:$H$175,"A medias") | F23: =COUNTIFS(Pruebas!$B$2:$B$175,"20. Informes",Pruebas!$H$2:$H$175,"Bloqueado") | G23: =COUNTIFS(Pruebas!$B$2:$B$175,"20. Informes",Pruebas!$H$2:$H$175,"")
A24: 21. Permisos | B24: =COUNTIF(Pruebas!$B$2:$B$175,"21. Permisos") | C24: =COUNTIFS(Pruebas!$B$2:$B$175,"21. Permisos",Pruebas!$H$2:$H$175,"OK") | D24: =COUNTIFS(Pruebas!$B$2:$B$175,"21. Permisos",Pruebas!$H$2:$H$175,"Falla") | E24: =COUNTIFS(Pruebas!$B$2:$B$175,"21. Permisos",Pruebas!$H$2:$H$175,"A medias") | F24: =COUNTIFS(Pruebas!$B$2:$B$175,"21. Permisos",Pruebas!$H$2:$H$175,"Bloqueado") | G24: =COUNTIFS(Pruebas!$B$2:$B$175,"21. Permisos",Pruebas!$H$2:$H$175,"")
A25: 22. Interfaz y uso | B25: =COUNTIF(Pruebas!$B$2:$B$175,"22. Interfaz y uso") | C25: =COUNTIFS(Pruebas!$B$2:$B$175,"22. Interfaz y uso",Pruebas!$H$2:$H$175,"OK") | D25: =COUNTIFS(Pruebas!$B$2:$B$175,"22. Interfaz y uso",Pruebas!$H$2:$H$175,"Falla") | E25: =COUNTIFS(Pruebas!$B$2:$B$175,"22. Interfaz y uso",Pruebas!$H$2:$H$175,"A medias") | F25: =COUNTIFS(Pruebas!$B$2:$B$175,"22. Interfaz y uso",Pruebas!$H$2:$H$175,"Bloqueado") | G25: =COUNTIFS(Pruebas!$B$2:$B$175,"22. Interfaz y uso",Pruebas!$H$2:$H$175,"")
A26: Total | B26: =SUM(B4:B25) | C26: =SUM(C4:C25) | D26: =SUM(D4:D25) | E26: =SUM(E4:E25) | F26: =SUM(F4:F25) | G26: =SUM(G4:G25)
A28: Bloqueantes abiertos | B28: =COUNTIF(Pruebas!$I$2:$I$175,"Bloqueante")
